{"type":"ticker","sequence":4573672992,"product_id":"BTC-USD","time":"0001-01-01T00:00:00Z","price":"17716.06000000","best_bid":"17716.05","best_ask":"17716.06","received_at":"2017-12-16T01:36:09"}
{"type":"l2update","product_id":"BTC-USD","time":"2017-12-15T23:36:08.749Z","changes":[["buy","17708.35000000","0.02821662"]],"received_at":"2017-12-16T01:36:09"}
{"type":"l2update","product_id":"BTC-USD","time":"2017-12-15T23:36:08.75Z","changes":[["sell","17955.58000000","1"]],"received_at":"2017-12-16T01:36:09"}
{"type":"l2update","product_id":"BTC-USD","time":"2017-12-15T23:36:08.808Z","changes":[["sell","17963.58000000","2"]],"received_at":"2017-12-16T01:36:09"}
{"type":"l2update","product_id":"BTC-USD","time":"2017-12-15T23:36:08.817Z","changes":[["sell","17779.72000000","0.04"]],"received_at":"2017-12-16T01:36:09"}
{"type":"heartbeat","sequence":4573673062,"last_trade_id":28428921,"product_id":"BTC-USD","time":"2017-12-15T23:36:08.825Z","received_at":"2017-12-16T01:36:09"}
{"type":"l2update","product_id":"BTC-USD","time":"2017-12-15T23:36:08.899Z","changes":[["buy","17708.35000000","0.01823526"]],"received_at":"2017-12-16T01:36:09"}
{"type":"l2update","product_id":"BTC-USD","time":"2017-12-15T23:36:08.917Z","changes":[["buy","17600.00000000","21.93985826"]],"received_at":"2017-12-16T01:36:09"}
{"type":"l2update","product_id":"BTC-USD","time":"2017-12-15T23:36:08.936Z","changes":[["sell","17971.58000000","3"]],"received_at":"2017-12-16T01:36:09"}
{"type":"l2update","product_id":"BTC-USD","time":"2017-12-15T23:36:08.94Z","changes":[["buy","17708.52000000","0.01298136"]],"received_at":"2017-12-16T01:36:09"}
{"type":"l2update","product_id":"BTC-USD","time":"2017-12-15T23:36:08.962Z","changes":[["sell","17730.30000000","0.3821"]],"received_at":"2017-12-16T01:36:09"}
{"type":"l2update","product_id":"BTC-USD","time":"2017-12-15T23:36:08.974Z","changes":[["sell","17779.72000000","0"]],"received_at":"2017-12-16T01:36:09"}
{"type":"l2update","product_id":"BTC-USD","time":"2017-12-15T23:36:09.079Z","changes":[["buy","17716.05000000","12.35869284"]],"received_at":"2017-12-16T01:36:09"}
{"type":"l2update","product_id":"BTC-USD","time":"2017-12-15T23:36:09.088Z","changes":[["sell","17730.34000000","0.27773778"]],"received_at":"2017-12-16T01:36:09"}
{"type":"l2update","product_id":"BTC-USD","time":"2017-12-15T23:36:09.118Z","changes":[["sell","17730.34000000","0.28773778"]],"received_at":"2017-12-16T01:36:09"}
{"type":"l2update","product_id":"BTC-USD","time":"2017-12-15T23:36:09.124Z","changes":[["buy","17708.52000000","0.003"]],"received_at":"2017-12-16T01:36:09"}
{"type":"l2update","product_id":"BTC-USD","time":"2017-12-15T23:36:09.137Z","changes":[["sell","17779.35000000","0.04"]],"received_at":"2017-12-16T01:36:09"}
{"type":"l2update","product_id":"BTC-USD","time":"2017-12-15T23:36:09.167Z","changes":[["sell","17871.85000000","0"]],"received_at":"2017-12-16T01:36:09"}
{"type":"l2update","product_id":"BTC-USD","time":"2017-12-15T23:36:09.195Z","changes":[["buy","17708.35000000","0.02821662"]],"received_at":"2017-12-16T01:36:09"}
{"type":"l2update","product_id":"BTC-USD","time":"2017-12-15T23:36:09.196Z","changes":[["buy","13979.38000000","0.07153423"]],"received_at":"2017-12-16T01:36:09"}
{"type":"l2update","product_id":"BTC-USD","time":"2017-12-15T23:36:09.222Z","changes":[["buy","17701.74000000","0"]],"received_at":"2017-12-16T01:36:09"}
{"type":"l2update","product_id":"BTC-USD","time":"2017-12-15T23:36:09.275Z","changes":[["sell","17716.06000000","10.68416664"]],"received_at":"2017-12-16T01:36:09"}
{"type":"ticker","sequence":4573673088,"product_id":"BTC-USD","time":"2017-12-15T23:36:09.271Z","trade_id":28428922,"price":"17716.06000000","side":"buy","last_size":"0.00005630","best_bid":"17716.05","best_ask":"17716.06","received_at":"2017-12-16T01:36:09"}
{"type":"l2update","product_id":"BTC-USD","time":"2017-12-15T23:36:09.279Z","changes":[["sell","17779.35000000","0"]],"received_at":"2017-12-16T01:36:09"}
{"type":"l2update","product_id":"BTC-USD","time":"2017-12-15T23:36:09.297Z","changes":[["buy","17700.84000000","0"]],"received_at":"2017-12-16T01:36:09"}
{"type":"l2update","product_id":"BTC-USD","time":"2017-12-15T23:36:09.312Z","changes":[["sell","17955.58000000","0"]],"received_at":"2017-12-16T01:36:09"}
{"type":"l2update","product_id":"BTC-USD","time":"2017-12-15T23:36:09.313Z","changes":[["buy","17700.82000000","1"]],"received_at":"2017-12-16T01:36:09"}
{"type":"l2update","product_id":"BTC-USD","time":"2017-12-15T23:36:09.316Z","changes":[["buy","17684.51000000","0"]],"received_at":"2017-12-16T01:36:09"}
{"type":"l2update","product_id":"BTC-USD","time":"2017-12-15T23:36:09.321Z","changes":[["buy","17708.35000000","0.01823526"]],"received_at":"2017-12-16T01:36:09"}
{"type":"l2update","product_id":"BTC-USD","time":"2017-12-15T23:36:09.332Z","changes":[["buy","17684.51000000","0.02"]],"received_at":"2017-12-16T01:36:09"}
{"type":"l2update","product_id":"BTC-USD","time":"2017-12-15T23:36:09.399Z","changes":[["sell","17963.58000000","0"]],"received_at":"2017-12-16T01:36:09"}
{"type":"l2update","product_id":"BTC-USD","time":"2017-12-15T23:36:09.444Z","changes":[["buy","17708.52000000","0.01298136"]],"received_at":"2017-12-16T01:36:09"}
{"type":"l2update","product_id":"BTC-USD","time":"2017-12-15T23:36:09.502Z","changes":[["sell","17971.58000000","0"]],"received_at":"2017-12-16T01:36:09"}
{"type":"l2update","product_id":"BTC-USD","time":"2017-12-15T23:36:09.546Z","changes":[["sell","17779.23000000","0.04"]],"received_at":"2017-12-16T01:36:09"}
{"type":"l2update","product_id":"BTC-USD","time":"2017-12-15T23:36:09.565Z","changes":[["sell","17779.23000000","0"]],"received_at":"2017-12-16T01:36:09"}
{"type":"l2update","product_id":"BTC-USD","time":"2017-12-15T23:36:09.592Z","changes":[["buy","17708.52000000","0.003"]],"received_at":"2017-12-16T01:36:09"}
{"type":"l2update","product_id":"BTC-USD","time":"2017-12-15T23:36:09.608Z","changes":[["sell","17955.08000000","1"]],"received_at":"2017-12-16T01:36:09"}
{"type":"l2update","product_id":"BTC-USD","time":"2017-12-15T23:36:09.713Z","changes":[["sell","17963.08000000","2"]],"received_at":"2017-12-16T01:36:09"}
{"type":"l2update","product_id":"BTC-USD","time":"2017-12-15T23:36:09.75Z","changes":[["sell","17730.30000000","0"]],"received_at":"2017-12-16T01:36:09"}
{"type":"l2update","product_id":"BTC-USD","time":"2017-12-15T23:36:09.775Z","changes":[["buy","17580.00000000","0.38384051"]],"received_at":"2017-12-16T01:36:09"}
{"type":"l2update","product_id":"BTC-USD","time":"2017-12-15T23:36:09.798Z","changes":[["sell","17971.08000000","3"]],"received_at":"2017-12-16T01:36:09"}
{"type":"heartbeat","sequence":4573673114,"last_trade_id":28428922,"product_id":"BTC-USD","time":"2017-12-15T23:36:09.825Z","received_at":"2017-12-16T01:36:09"}
{"type":"l2update","product_id":"BTC-USD","time":"2017-12-15T23:36:09.828Z","changes":[["sell","17778.71000000","0.04"]],"received_at":"2017-12-16T01:36:09"}
{"type":"l2update","product_id":"BTC-USD","time":"2017-12-15T23:36:09.831Z","changes":[["sell","17730.30000000","0.3821"]],"received_at":"2017-12-16T01:36:09"}
{"type":"l2update","product_id":"BTC-USD","time":"2017-12-15T23:36:09.842Z","changes":[["buy","17705.00000000","0.01133991"]],"received_at":"2017-12-16T01:36:09"}
{"type":"l2update","product_id":"BTC-USD","time":"2017-12-15T23:36:09.857Z","changes":[["buy","17716.05000000","12.17535877"]],"received_at":"2017-12-16T01:36:09"}
{"type":"ticker","sequence":4573673122,"product_id":"BTC-USD","time":"2017-12-15T23:36:09.859Z","trade_id":28428923,"price":"17716.05000000","side":"sell","last_size":"0.18333407","best_bid":"17716.05","best_ask":"17716.06","received_at":"2017-12-16T01:36:09"}
{"type":"l2update","product_id":"BTC-USD","time":"2017-12-15T23:36:09.9Z","changes":[["sell","17778.71000000","0"]],"received_at":"2017-12-16T01:36:09"}
{"type":"l2update","product_id":"BTC-USD","time":"2017-12-15T23:36:09.978Z","changes":[["buy","17705.00000000","0.00135855"]],"received_at":"2017-12-16T01:36:10"}
{"type":"l2update","product_id":"BTC-USD","time":"2017-12-15T23:36:10.006Z","changes":[["sell","17730.32000000","0.6330604"]],"received_at":"2017-12-16T01:36:10"}
{"type":"l2update","product_id":"BTC-USD","time":"2017-12-15T23:36:10.02Z","changes":[["sell","17730.30000000","0"]],"received_at":"2017-12-16T01:36:10"}
{"type":"l2update","product_id":"BTC-USD","time":"2017-12-15T23:36:10.191Z","changes":[["sell","17729.89000000","0.3842"]],"received_at":"2017-12-16T01:36:10"}
{"type":"l2update","product_id":"BTC-USD","time":"2017-12-15T23:36:10.192Z","changes":[["sell","17730.32000000","0.6430604"]],"received_at":"2017-12-16T01:36:10"}
{"type":"l2update","product_id":"BTC-USD","time":"2017-12-15T23:36:10.199Z","changes":[["sell","17777.94000000","0.04"]],"received_at":"2017-12-16T01:36:10"}
{"type":"l2update","product_id":"BTC-USD","time":"2017-12-15T23:36:10.216Z","changes":[["sell","17730.34000000","0.27773778"]],"received_at":"2017-12-16T01:36:10"}
{"type":"l2update","product_id":"BTC-USD","time":"2017-12-15T23:36:10.248Z","changes":[["sell","17730.34000000","0.28773778"]],"received_at":"2017-12-16T01:36:10"}
{"type":"l2update","product_id":"BTC-USD","time":"2017-12-15T23:36:10.282Z","changes":[["buy","17708.52000000","0.01298136"]],"received_at":"2017-12-16T01:36:10"}
{"type":"l2update","product_id":"BTC-USD","time":"2017-12-15T23:36:10.34Z","changes":[["sell","17729.90000000","2.686"]],"received_at":"2017-12-16T01:36:10"}
{"type":"l2update","product_id":"BTC-USD","time":"2017-12-15T23:36:10.346Z","changes":[["sell","17730.32000000","0.6330604"]],"received_at":"2017-12-16T01:36:10"}
{"type":"l2update","product_id":"BTC-USD","time":"2017-12-15T23:36:10.361Z","changes":[["buy","16500.00000000","140.27874942"]],"received_at":"2017-12-16T01:36:10"}
{"type":"l2update","product_id":"BTC-USD","time":"2017-12-15T23:36:10.42Z","changes":[["buy","17708.52000000","0.003"]],"received_at":"2017-12-16T01:36:10"}
{"type":"l2update","product_id":"BTC-USD","time":"2017-12-15T23:36:10.46Z","changes":[["buy","17684.51000000","0"]],"received_at":"2017-12-16T01:36:10"}
{"type":"l2update","product_id":"BTC-USD","time":"2017-12-15T23:36:10.469Z","changes":[["buy","17684.51000000","0.02"]],"received_at":"2017-12-16T01:36:10"}
{"type":"l2update","product_id":"BTC-USD","time":"2017-12-15T23:36:10.476Z","changes":[["sell","17777.94000000","0"]],"received_at":"2017-12-16T01:36:10"}
{"type":"l2update","product_id":"BTC-USD","time":"2017-12-15T23:36:10.524Z","changes":[["sell","17778.39000000","0.04"]],"received_at":"2017-12-16T01:36:10"}
{"type":"l2update","product_id":"BTC-USD","time":"2017-12-15T23:36:10.568Z","changes":[["buy","17708.52000000","0.01298136"]],"received_at":"2017-12-16T01:36:10"}
{"type":"l2update","product_id":"BTC-USD","time":"2017-12-15T23:36:10.658Z","changes":[["sell","17729.90000000","2.676"]],"received_at":"2017-12-16T01:36:10"}
{"type":"l2update","product_id":"BTC-USD","time":"2017-12-15T23:36:10.694Z","changes":[["sell","17729.90000000","2.686"]],"received_at":"2017-12-16T01:36:10"}
{"type":"l2update","product_id":"BTC-USD","time":"2017-12-15T23:36:10.754Z","changes":[["buy","17708.52000000","0.003"]],"received_at":"2017-12-16T01:36:10"}
{"type":"l2update","product_id":"BTC-USD","time":"2017-12-15T23:36:10.831Z","changes":[["sell","17778.39000000","0"]],"received_at":"2017-12-16T01:36:10"}
{"type":"l2update","product_id":"BTC-USD","time":"2017-12-15T23:36:10.832Z","changes":[["sell","17729.90000000","2.676"]],"received_at":"2017-12-16T01:36:10"}
{"type":"heartbeat","sequence":4573673158,"last_trade_id":28428923,"product_id":"BTC-USD","time":"2017-12-15T23:36:10.825Z","received_at":"2017-12-16T01:36:10"}
{"type":"l2update","product_id":"BTC-USD","time":"2017-12-15T23:36:10.834Z","changes":[["buy","16999.00000000","10.26680632"]],"received_at":"2017-12-16T01:36:10"}
{"type":"l2update","product_id":"BTC-USD","time":"2017-12-15T23:36:10.86Z","changes":[["buy","17708.52000000","0.01298136"]],"received_at":"2017-12-16T01:36:10"}
{"type":"l2update","product_id":"BTC-USD","time":"2017-12-15T23:36:10.868Z","changes":[["sell","17778.26000000","0.04"]],"received_at":"2017-12-16T01:36:10"}
{"type":"l2update","product_id":"BTC-USD","time":"2017-12-15T23:36:10.916Z","changes":[["sell","17729.90000000","2.686"]],"received_at":"2017-12-16T01:36:10"}
{"type":"l2update","product_id":"BTC-USD","time":"2017-12-15T23:36:10.924Z","changes":[["buy","17620.00000000","3.90464545"]],"received_at":"2017-12-16T01:36:10"}
{"type":"l2update","product_id":"BTC-USD","time":"2017-12-15T23:36:10.97Z","changes":[["sell","17778.26000000","0"]],"received_at":"2017-12-16T01:36:11"}
{"type":"l2update","product_id":"BTC-USD","time":"2017-12-15T23:36:11.01Z","changes":[["buy","17708.52000000","0.003"]],"received_at":"2017-12-16T01:36:11"}
